ModuleCmd_Use.c(231):ERROR:64: Directory '/home/groudko/.modulefiles/' not found
>>> Loading modules from /g/scb2/bork/mocat/software/bork_modulefiles/ <<<
Python path configuration:
  PYTHONHOME = (not set)
  PYTHONPATH = (not set)
  program name = '/g/scb2/bork/mocat/software/gunc/1.0.1-gtdb/miniconda3/envs/gunc-gtdb/bin/python3.9'
  isolated = 0
  environment = 1
  user site = 1
  import site = 1
  sys._base_executable = '/g/scb2/bork/mocat/software/gunc/1.0.1-gtdb/miniconda3/envs/gunc-gtdb/bin/python3.9'
  sys.base_prefix = '/g/scb2/bork/mocat/software/gunc/1.0.1-gtdb/miniconda3/envs/gunc-gtdb'
  sys.base_exec_prefix = '/g/scb2/bork/mocat/software/gunc/1.0.1-gtdb/miniconda3/envs/gunc-gtdb'
  sys.platlibdir = 'lib'
  sys.executable = '/g/scb2/bork/mocat/software/gunc/1.0.1-gtdb/miniconda3/envs/gunc-gtdb/bin/python3.9'
  sys.prefix = '/g/scb2/bork/mocat/software/gunc/1.0.1-gtdb/miniconda3/envs/gunc-gtdb'
  sys.exec_prefix = '/g/scb2/bork/mocat/software/gunc/1.0.1-gtdb/miniconda3/envs/gunc-gtdb'
  sys.path = [
    '/g/scb2/bork/mocat/software/gunc/1.0.1-gtdb/miniconda3/envs/gunc-gtdb/lib/python39.zip',
    '/g/scb2/bork/mocat/software/gunc/1.0.1-gtdb/miniconda3/envs/gunc-gtdb/lib/python3.9',
    '/g/scb2/bork/mocat/software/gunc/1.0.1-gtdb/miniconda3/envs/gunc-gtdb/lib/python3.9/lib-dynload',
  ]
Fatal Python error: init_fs_encoding: failed to get the Python codec of the filesystem encoding
Python runtime state: core initialized
ModuleNotFoundError: No module named 'encodings'

Current thread 0x00007f31160b9740 (most recent call first):
<no Python frame>
srun: error: compute-0-4: task 0: Exited with exit code 1
awk: fatal: cannot open file `*diamond.out.diamond.out' for reading (No such file or directory)
mkdir: cannot create directory '4.1_refine_output/Fusobacterium_nucleatum/gunc/refinement': File exists
Traceback (most recent call last):
  File "/g/scb2/bork/groudko/scripts/refine_gunc.py", line 435, in <module>
    file = pd.read_csv(gunc_folder_path+'/refinement/merged.faa', header = None)
  File "/g/scb2/bork/mocat/software/gunc/1.0.1-gtdb/gunc/lib/python3.9/site-packages/pandas/io/parsers.py", line 610, in read_csv
    return _read(filepath_or_buffer, kwds)
  File "/g/scb2/bork/mocat/software/gunc/1.0.1-gtdb/gunc/lib/python3.9/site-packages/pandas/io/parsers.py", line 462, in _read
    parser = TextFileReader(filepath_or_buffer, **kwds)
  File "/g/scb2/bork/mocat/software/gunc/1.0.1-gtdb/gunc/lib/python3.9/site-packages/pandas/io/parsers.py", line 819, in __init__
    self._engine = self._make_engine(self.engine)
  File "/g/scb2/bork/mocat/software/gunc/1.0.1-gtdb/gunc/lib/python3.9/site-packages/pandas/io/parsers.py", line 1050, in _make_engine
    return mapping[engine](self.f, **self.options)  # type: ignore[call-arg]
  File "/g/scb2/bork/mocat/software/gunc/1.0.1-gtdb/gunc/lib/python3.9/site-packages/pandas/io/parsers.py", line 1898, in __init__
    self._reader = parsers.TextReader(self.handles.handle, **kwds)
  File "pandas/_libs/parsers.pyx", line 521, in pandas._libs.parsers.TextReader.__cinit__
pandas.errors.EmptyDataError: No columns to parse from file
srun: error: compute-0-5: task 0: Exited with exit code 1
mkdir: cannot create directory '/g/scb/bork/groudko/ref_v1.1/4.1_refine_output/Fusobacterium_nucleatum/gunc/refinement/refined_genomes': File exists
mkdir: cannot create directory '/g/scb/bork/groudko/ref_v1.1/4.1_refine_output/Fusobacterium_nucleatum/gunc/refinement/refined_genomes/None_refined': File exists
Traceback (most recent call last):
  File "/g/scb2/bork/groudko/scripts/step2_refine_gunc.py", line 113, in <module>
    gunc_stats=pd.read_csv(os.path.join(refine_out,'../GUNC.maxCSS_level.tsv'),sep='\t')
  File "/g/scb2/bork/mocat/software/gunc/1.0.1-gtdb/gunc/lib/python3.9/site-packages/pandas/io/parsers.py", line 610, in read_csv
    return _read(filepath_or_buffer, kwds)
  File "/g/scb2/bork/mocat/software/gunc/1.0.1-gtdb/gunc/lib/python3.9/site-packages/pandas/io/parsers.py", line 462, in _read
    parser = TextFileReader(filepath_or_buffer, **kwds)
  File "/g/scb2/bork/mocat/software/gunc/1.0.1-gtdb/gunc/lib/python3.9/site-packages/pandas/io/parsers.py", line 819, in __init__
    self._engine = self._make_engine(self.engine)
  File "/g/scb2/bork/mocat/software/gunc/1.0.1-gtdb/gunc/lib/python3.9/site-packages/pandas/io/parsers.py", line 1050, in _make_engine
    return mapping[engine](self.f, **self.options)  # type: ignore[call-arg]
  File "/g/scb2/bork/mocat/software/gunc/1.0.1-gtdb/gunc/lib/python3.9/site-packages/pandas/io/parsers.py", line 1867, in __init__
    self._open_handles(src, kwds)
  File "/g/scb2/bork/mocat/software/gunc/1.0.1-gtdb/gunc/lib/python3.9/site-packages/pandas/io/parsers.py", line 1362, in _open_handles
    self.handles = get_handle(
  File "/g/scb2/bork/mocat/software/gunc/1.0.1-gtdb/gunc/lib/python3.9/site-packages/pandas/io/common.py", line 642, in get_handle
    handle = open(
FileNotFoundError: [Errno 2] No such file or directory: '/g/scb/bork/groudko/ref_v1.1/4.1_refine_output/Fusobacterium_nucleatum/gunc/refinement/../GUNC.maxCSS_level.tsv'
ln: failed to create symbolic link '4.2_output_n_stats/Fusobacterium_nucleatum/*fa': File exists
[ERROR] No files found in . with ending .fa
srun: error: compute-0-10: task 0: Exited with exit code 1
[08/23/2022 12:52:21 AM] INFO: Running quality prediction workflow with 32 threads.
[08/23/2022 12:52:21 AM] ERROR: No bins found. Check the extension (-x) used to identify bins.
srun: error: compute-0-10: task 0: Exited with exit code 1
Traceback (most recent call last):
  File "/g/scb2/bork/groudko/scripts/ref_v1.1/merge_gunc_checkm2_3.py", line 44, in <module>
    new_checkm=pd.read_csv(new_checkm_file, sep='\t',usecols=['Name','Completeness','Contamination'])
  File "/g/scb2/bork/mocat/software/gunc/1.0.1-gtdb/gunc/lib/python3.9/site-packages/pandas/io/parsers.py", line 610, in read_csv
    return _read(filepath_or_buffer, kwds)
  File "/g/scb2/bork/mocat/software/gunc/1.0.1-gtdb/gunc/lib/python3.9/site-packages/pandas/io/parsers.py", line 462, in _read
    parser = TextFileReader(filepath_or_buffer, **kwds)
  File "/g/scb2/bork/mocat/software/gunc/1.0.1-gtdb/gunc/lib/python3.9/site-packages/pandas/io/parsers.py", line 819, in __init__
    self._engine = self._make_engine(self.engine)
  File "/g/scb2/bork/mocat/software/gunc/1.0.1-gtdb/gunc/lib/python3.9/site-packages/pandas/io/parsers.py", line 1050, in _make_engine
    return mapping[engine](self.f, **self.options)  # type: ignore[call-arg]
  File "/g/scb2/bork/mocat/software/gunc/1.0.1-gtdb/gunc/lib/python3.9/site-packages/pandas/io/parsers.py", line 1867, in __init__
    self._open_handles(src, kwds)
  File "/g/scb2/bork/mocat/software/gunc/1.0.1-gtdb/gunc/lib/python3.9/site-packages/pandas/io/parsers.py", line 1362, in _open_handles
    self.handles = get_handle(
  File "/g/scb2/bork/mocat/software/gunc/1.0.1-gtdb/gunc/lib/python3.9/site-packages/pandas/io/common.py", line 642, in get_handle
    handle = open(
FileNotFoundError: [Errno 2] No such file or directory: '/g/scb/bork/groudko/ref_v1.1/4.2_output_n_stats/Fusobacterium_nucleatum/checkm2/quality_report.tsv'
During startup - Warning message:
Setting LC_CTYPE failed, using "C" 
Loading required package: ggplot2
Warning message:
package 'ggplot2' was built under R version 4.1.3 
Loading required package: ggalluvial
Loading required package: scales
Warning message:
package 'scales' was built under R version 4.1.3 
Loading required package: munsell
Loading required package: dplyr

Attaching package: 'dplyr'

The following objects are masked from 'package:stats':

    filter, lag

The following objects are masked from 'package:base':

    intersect, setdiff, setequal, union

Warning message:
package 'dplyr' was built under R version 4.1.3 
Error in file(file, "rt") : cannot open the connection
Calls: read.csv -> read.table -> file
In addition: Warning message:
In file(file, "rt") :
  cannot open file 'results.tsv': No such file or directory
Execution halted
